<?xml version="1.0" encoding="UTF-8"?>
<testng-results ignored="0" total="2" passed="1" failed="1" skipped="0">
  <reporter-output>
  </reporter-output>
  <suite started-at="2024-05-03T13:42:48Z" name="Default suite" finished-at="2024-05-03T13:43:14Z" duration-ms="26494">
    <groups>
      <group name="Regression">
        <method signature="LoginSuite.TC_LF_001_VerifyUserLoginIntoApplicationWithValidCredentials()[pri:1, instance:com.qa.tests.LoginSuite@27953a83]" name="TC_LF_001_VerifyUserLoginIntoApplicationWithValidCredentials" class="com.qa.tests.LoginSuite"/>
        <method signature="LoginSuite.TC_LF_002_VerifyUserLoginIntoApplicationWithInvalidCredentials()[pri:2, instance:com.qa.tests.LoginSuite@27953a83]" name="TC_LF_002_VerifyUserLoginIntoApplicationWithInvalidCredentials" class="com.qa.tests.LoginSuite"/>
      </group> <!-- Regression -->
      <group name="Login">
        <method signature="LoginSuite.TC_LF_001_VerifyUserLoginIntoApplicationWithValidCredentials()[pri:1, instance:com.qa.tests.LoginSuite@27953a83]" name="TC_LF_001_VerifyUserLoginIntoApplicationWithValidCredentials" class="com.qa.tests.LoginSuite"/>
        <method signature="LoginSuite.TC_LF_002_VerifyUserLoginIntoApplicationWithInvalidCredentials()[pri:2, instance:com.qa.tests.LoginSuite@27953a83]" name="TC_LF_002_VerifyUserLoginIntoApplicationWithInvalidCredentials" class="com.qa.tests.LoginSuite"/>
      </group> <!-- Login -->
    </groups>
    <test started-at="2024-05-03T13:42:48Z" name="Default test" finished-at="2024-05-03T13:43:14Z" duration-ms="26494">
      <class name="com.qa.tests.LoginSuite">
        <test-method signature="TC_LF_001_VerifyUserLoginIntoApplicationWithValidCredentials()[pri:1, instance:com.qa.tests.LoginSuite@27953a83]" started-at="2024-05-03T13:42:48Z" name="TC_LF_001_VerifyUserLoginIntoApplicationWithValidCredentials" description="TC_LF_001:Verify that user is able to login successfully in the ParaBank application with valid username and password" finished-at="2024-05-03T13:43:02Z" duration-ms="14540" status="FAIL">
          <exception class="java.lang.AssertionError">
            <message>
              <![CDATA[expected [true] but found [false]]]>
            </message>
            <full-stacktrace>
              <![CDATA[java.lang.AssertionError: expected [true] but found [false]
at org.testng.Assert.fail(Assert.java:96)
at org.testng.Assert.failNotEquals(Assert.java:776)
at org.testng.Assert.assertTrue(Assert.java:44)
at org.testng.Assert.assertTrue(Assert.java:54)
at com.qa.tests.LoginSuite.TC_LF_001_VerifyUserLoginIntoApplicationWithValidCredentials(LoginSuite.java:51)
at java.base/jdk.internal.reflect.NativeMethodAccessorImpl.invoke0(Native Method)
at java.base/jdk.internal.reflect.NativeMethodAccessorImpl.invoke(NativeMethodAccessorImpl.java:77)
at java.base/jdk.internal.reflect.DelegatingMethodAccessorImpl.invoke(DelegatingMethodAccessorImpl.java:43)
at java.base/java.lang.reflect.Method.invoke(Method.java:568)
at org.testng.internal.MethodInvocationHelper.invokeMethod(MethodInvocationHelper.java:124)
at org.testng.internal.Invoker.invokeMethod(Invoker.java:583)
at org.testng.internal.Invoker.invokeTestMethod(Invoker.java:719)
at org.testng.internal.Invoker.invokeTestMethods(Invoker.java:989)
at org.testng.internal.TestMethodWorker.invokeTestMethods(TestMethodWorker.java:125)
at org.testng.internal.TestMethodWorker.run(TestMethodWorker.java:109)
at org.testng.TestRunner.privateRun(TestRunner.java:648)
at org.testng.TestRunner.run(TestRunner.java:505)
at org.testng.SuiteRunner.runTest(SuiteRunner.java:455)
at org.testng.SuiteRunner.runSequentially(SuiteRunner.java:450)
at org.testng.SuiteRunner.privateRun(SuiteRunner.java:415)
at org.testng.SuiteRunner.run(SuiteRunner.java:364)
at org.testng.SuiteRunnerWorker.runSuite(SuiteRunnerWorker.java:52)
at org.testng.SuiteRunnerWorker.run(SuiteRunnerWorker.java:84)
at org.testng.TestNG.runSuitesSequentially(TestNG.java:1208)
at org.testng.TestNG.runSuitesLocally(TestNG.java:1137)
at org.testng.TestNG.runSuites(TestNG.java:1049)
at org.testng.TestNG.run(TestNG.java:1017)
at org.testng.remote.AbstractRemoteTestNG.run(AbstractRemoteTestNG.java:115)
at org.testng.remote.RemoteTestNG.initAndRun(RemoteTestNG.java:251)
at org.testng.remote.RemoteTestNG.main(RemoteTestNG.java:77)
]]>
            </full-stacktrace>
          </exception> <!-- java.lang.AssertionError -->
          <reporter-output>
          </reporter-output>
        </test-method> <!-- TC_LF_001_VerifyUserLoginIntoApplicationWithValidCredentials -->
        <test-method is-config="true" signature="tearDown()[pri:0, instance:com.qa.tests.LoginSuite@27953a83]" started-at="2024-05-03T13:43:03Z" name="tearDown" finished-at="2024-05-03T13:43:03Z" duration-ms="362" status="PASS">
          <reporter-output>
          </reporter-output>
        </test-method> <!-- tearDown -->
        <test-method signature="TC_LF_002_VerifyUserLoginIntoApplicationWithInvalidCredentials()[pri:2, instance:com.qa.tests.LoginSuite@27953a83]" started-at="2024-05-03T13:43:03Z" name="TC_LF_002_VerifyUserLoginIntoApplicationWithInvalidCredentials" description="TC_LF_002:Verify that user is able to login successfully in the ParaBank application with Invalid username and password" finished-at="2024-05-03T13:43:13Z" duration-ms="9932" status="PASS">
          <reporter-output>
          </reporter-output>
        </test-method> <!-- TC_LF_002_VerifyUserLoginIntoApplicationWithInvalidCredentials -->
        <test-method is-config="true" signature="tearDown()[pri:0, instance:com.qa.tests.LoginSuite@27953a83]" started-at="2024-05-03T13:43:13Z" name="tearDown" finished-at="2024-05-03T13:43:14Z" duration-ms="1097" status="PASS">
          <reporter-output>
          </reporter-output>
        </test-method> <!-- tearDown -->
      </class> <!-- com.qa.tests.LoginSuite -->
    </test> <!-- Default test -->
  </suite> <!-- Default suite -->
</testng-results>
